Workbook

Sheet Restaurantes
A1: # | B1: Prioridad | C1: Restaurante | D1: Ciudad | E1: Zona | F1: Tipo | G1: Teléfono | H1: Línea | I1: WhatsApp | J1: Dirección | K1: Estado | L1: Primer contacto | M1: Seguimiento | N1: Plan de interés | O1: Mensualidad | P1: Próxima acción | Q1: Notas | R1: Pedidos por WhatsApp | S1: Fuente
A2: 1 | B2: Alta | C2: A Otro Nivel Parrilla | D2: Bello | F2: Parrilla / comida rápida | G2: 3105435674 | H2: =IF(G2="","Sin número",IF(LEFT(G2,1)="3","Celular","Fijo")) -> Celular | I2: =IF(H2="Celular",HYPERLINK("https://wa.me/57"&G2,"Abrir chat"),"") -> Abrir chat | J2: Cl 57 # 67B-79 | K2: Por contactar | M2: =IF(L2="","",L2+4) | O2: =IF(N2="","",INDEX(Planes!$B$4:$B$6,MATCH(N2,Planes!$A$4:$A$6,0))) | P2: Enviar mensaje 1b | R2: Menú en línea con pedidos a WhatsApp (ola.click) | S2: =HYPERLINK("https://aotronivelparrilla.ola.click/","Ver fuente") -> Ver fuente
A3: 2 | B3: Alta | C3: Aquí Fue Trapiche | D3: Bello | F3: Restaurante | G3: 3224852584 | H3: =IF(G3="","Sin número",IF(LEFT(G3,1)="3","Celular","Fijo")) -> Celular | I3: =IF(H3="Celular",HYPERLINK("https://wa.me/57"&G3,"Abrir chat"),"") -> Abrir chat | J3: Cra 66 # 57-46 | K3: Por contactar | M3: =IF(L3="","",L3+4) | O3: =IF(N3="","",INDEX(Planes!$B$4:$B$6,MATCH(N3,Planes!$A$4:$A$6,0))) | P3: Enviar mensaje 1b | R3: Menú en línea con pedidos a WhatsApp (ola.click) | S3: =HYPERLINK("https://aquifuedomicilio.ola.click/","Ver fuente") -> Ver fuente
A4: 3 | B4: Alta | C4: Arroz Caracas | D4: Bello | F4: Comida china | H4: =IF(G4="","Sin número",IF(LEFT(G4,1)="3","Celular","Fijo")) -> Sin número | I4: =IF(H4="Celular",HYPERLINK("https://wa.me/57"&G4,"Abrir chat"),"") | K4: Por contactar | M4: =IF(L4="","",L4+4) | O4: =IF(N4="","",INDEX(Planes!$B$4:$B$6,MATCH(N4,Planes!$A$4:$A$6,0))) | P4: Escribir por el botón de WhatsApp de su menú en línea | R4: Menú en línea con pedidos a WhatsApp; reparte en Cabañas, París y Santa Ana (ola.click) | S4: =HYPERLINK("https://arroz-caracas.ola.click/info","Ver fuente") -> Ver fuente
A5: 4 | B5: Alta | C5: Carnes al Carbón Valadares | D5: Bello | F5: Asados | H5: =IF(G5="","Sin número",IF(LEFT(G5,1)="3","Celular","Fijo")) -> Sin número | I5: =IF(H5="Celular",HYPERLINK("https://wa.me/57"&G5,"Abrir chat"),"") | J5: Cra 66BB # 57A-34 | K5: Por contactar | M5: =IF(L5="","",L5+4) | O5: =IF(N5="","",INDEX(Planes!$B$4:$B$6,MATCH(N5,Planes!$A$4:$A$6,0))) | P5: Escribir por el botón de WhatsApp de su menú en línea | R5: Menú en línea con pedidos a WhatsApp (ola.click) | S5: =HYPERLINK("https://carnesalcarbonvaladares.ola.click/","Ver fuente") -> Ver fuente
A6: 5 | B6: Alta | C6: Family Restorant Bar & Grill | D6: Bello | E6: Andalucía | F6: Hamburguesas / parrilla | G6: 3232803762 | H6: =IF(G6="","Sin número",IF(LEFT(G6,1)="3","Celular","Fijo")) -> Celular | I6: =IF(H6="Celular",HYPERLINK("https://wa.me/57"&G6,"Abrir chat"),"") -> Abrir chat | J6: Cl 55 # 52-26 | K6: Por contactar | M6: =IF(L6="","",L6+4) | O6: =IF(N6="","",INDEX(Planes!$B$4:$B$6,MATCH(N6,Planes!$A$4:$A$6,0))) | P6: Enviar mensaje 1b | R6: Menú en línea con pedidos a WhatsApp (ola.click) | S6: =HYPERLINK("https://familyburger-col.ola.click/","Ver fuente") -> Ver fuente
A7: 6 | B7: Alta | C7: Garage Burger 66 | D7: Bello | E7: La Madera | F7: Hamburguesas | H7: =IF(G7="","Sin número",IF(LEFT(G7,1)="3","Celular","Fijo")) -> Sin número | I7: =IF(H7="Celular",HYPERLINK("https://wa.me/57"&G7,"Abrir chat"),"") | J7: Cra 53 # 26B-26 | K7: Por contactar | M7: =IF(L7="","",L7+4) | O7: =IF(N7="","",INDEX(Planes!$B$4:$B$6,MATCH(N7,Planes!$A$4:$A$6,0))) | P7: Escribir por el botón de WhatsApp de su menú en línea | R7: Menú en línea con pedidos a WhatsApp (ola.click) | S7: =HYPERLINK("https://garage-burger-66.ola.click/","Ver fuente") -> Ver fuente
A8: 7 | B8: Alta | C8: GUSLAB | D8: Bello | E8: La Mesa | F8: Restaurante | G8: 3332578535 | H8: =IF(G8="","Sin número",IF(LEFT(G8,1)="3","Celular","Fijo")) -> Celular | I8: =IF(H8="Celular",HYPERLINK("https://wa.me/57"&G8,"Abrir chat"),"") -> Abrir chat | J8: Cl 53A # 52-39 | K8: Por contactar | M8: =IF(L8="","",L8+4) | O8: =IF(N8="","",INDEX(Planes!$B$4:$B$6,MATCH(N8,Planes!$A$4:$A$6,0))) | P8: Enviar mensaje 1b | R8: Menú en línea con pedidos a WhatsApp (ola.click) | S8: =HYPERLINK("https://guslab.ola.click/","Ver fuente") -> Ver fuente
A9: 8 | B9: Alta | C9: Los Mandingos | D9: Bello | E9: La Cabaña | F9: Restaurante | H9: =IF(G9="","Sin número",IF(LEFT(G9,1)="3","Celular","Fijo")) -> Sin número | I9: =IF(H9="Celular",HYPERLINK("https://wa.me/57"&G9,"Abrir chat"),"") | K9: Por contactar | M9: =IF(L9="","",L9+4) | O9: =IF(N9="","",INDEX(Planes!$B$4:$B$6,MATCH(N9,Planes!$A$4:$A$6,0))) | P9: Escribir por el botón de WhatsApp de su menú en línea | R9: Menú en línea con pedidos a WhatsApp (ola.click) | S9: =HYPERLINK("https://los-mandingos.ola.click/","Ver fuente") -> Ver fuente
A10: 9 | B10: Alta | C10: Restaurante Cuernavaca | D10: Bello | E10: Centro | F10: Comida mexicana y típica | G10: 3187838904 | H10: =IF(G10="","Sin número",IF(LEFT(G10,1)="3","Celular","Fijo")) -> Celular | I10: =IF(H10="Celular",HYPERLINK("https://wa.me/57"&G10,"Abrir chat"),"") -> Abrir chat | J10: Cra 51 # 51-27 | K10: Por contactar | M10: =IF(L10="","",L10+4) | O10: =IF(N10="","",INDEX(Planes!$B$4:$B$6,MATCH(N10,Planes!$A$4:$A$6,0))) | P10: Enviar mensaje 1b | R10: Menú en línea con pedidos a WhatsApp (ola.click) | S10: =HYPERLINK("https://cuernavaca.ola.click/","Ver fuente") -> Ver fuente
A11: 10 | B11: Alta | C11: Alabama | D11: Medellín | E11: El Poblado | F11: Almuerzos caseros | H11: =IF(G11="","Sin número",IF(LEFT(G11,1)="3","Celular","Fijo")) -> Sin número | I11: =IF(H11="Celular",HYPERLINK("https://wa.me/57"&G11,"Abrir chat"),"") | K11: Por contactar | M11: =IF(L11="","",L11+4) | O11: =IF(N11="","",INDEX(Planes!$B$4:$B$6,MATCH(N11,Planes!$A$4:$A$6,0))) | P11: Escribir por el botón de WhatsApp de su menú en línea | R11: Manda el menú del día por WhatsApp y recibe los pedidos por ahí | S11: =HYPERLINK("https://alabama.soy/almuerzo-casero-medellin/","Ver fuente") -> Ver fuente
A12: 11 | B12: Alta | C12: Arepapas | D12: Medellín | E12: Laureles | F12: Arepería | G12: 3052572323 | H12: =IF(G12="","Sin número",IF(LEFT(G12,1)="3","Celular","Fijo")) -> Celular | I12: =IF(H12="Celular",HYPERLINK("https://wa.me/57"&G12,"Abrir chat"),"") -> Abrir chat | J12: Cl 43 # 76-10 | K12: Por contactar | M12: =IF(L12="","",L12+4) | O12: =IF(N12="","",INDEX(Planes!$B$4:$B$6,MATCH(N12,Planes!$A$4:$A$6,0))) | P12: Enviar mensaje 1b | R12: Menú en línea con pedidos a WhatsApp (ola.click) | S12: =HYPERLINK("https://arepapas.ola.click/","Ver fuente") -> Ver fuente
A13: 12 | B13: Alta | C13: Benditas Papas | D13: Medellín | E13: Buenos Aires | F13: Comida rápida | G13: 3137842015 | H13: =IF(G13="","Sin número",IF(LEFT(G13,1)="3","Celular","Fijo")) -> Celular | I13: =IF(H13="Celular",HYPERLINK("https://wa.me/57"&G13,"Abrir chat"),"") -> Abrir chat | J13: Cl 50 # 27A-87 | K13: Por contactar | M13: =IF(L13="","",L13+4) | O13: =IF(N13="","",INDEX(Planes!$B$4:$B$6,MATCH(N13,Planes!$A$4:$A$6,0))) | P13: Enviar mensaje 1b | R13: Menú en línea con pedidos a WhatsApp (ola.click) | S13: =HYPERLINK("https://benditas-papas.ola.click/","Ver fuente") -> Ver fuente
A14: 13 | B14: Alta | C14: Brosty Combo La Y | D14: Medellín | E14: Buenos Aires | F14: Asadero | G14: 3027017636 | H14: =IF(G14="","Sin número",IF(LEFT(G14,1)="3","Celular","Fijo")) -> Celular | I14: =IF(H14="Celular",HYPERLINK("https://wa.me/57"&G14,"Abrir chat"),"") -> Abrir chat | J14: Cl 49 # 7-10, Barrios de Jesús | K14: Por contactar | M14: =IF(L14="","",L14+4) | O14: =IF(N14="","",INDEX(Planes!$B$4:$B$6,MATCH(N14,Planes!$A$4:$A$6,0))) | P14: Enviar mensaje 1b | R14: Menú en línea con pedidos a WhatsApp (ola.click) | S14: =HYPERLINK("https://brosty-combo-la-y.ola.click/","Ver fuente") -> Ver fuente
A15: 14 | B15: Alta | C15: Bárbaro Cocina Primitiva | D15: Medellín | E15: El Poblado / Laureles | F15: Restaurante con domicilios | G15: 3176762292 | H15: =IF(G15="","Sin número",IF(LEFT(G15,1)="3","Celular","Fijo")) -> Celular | I15: =IF(H15="Celular",HYPERLINK("https://wa.me/57"&G15,"Abrir chat"),"") -> Abrir chat | K15: Por contactar | M15: =IF(L15="","",L15+4) | O15: =IF(N15="","",INDEX(Planes!$B$4:$B$6,MATCH(N15,Planes!$A$4:$A$6,0))) | P15: Enviar mensaje 1b | R15: Domicilios por WhatsApp (guía de 2020); Laureles: 3182822160 | S15: =HYPERLINK("https://medellinguru.com/?p=24707","Ver fuente") -> Ver fuente
A16: 15 | B16: Alta | C16: Casa del Arroz | D16: Medellín | E16: Belén | F16: Arroces | G16: 3019075390 | H16: =IF(G16="","Sin número",IF(LEFT(G16,1)="3","Celular","Fijo")) -> Celular | I16: =IF(H16="Celular",HYPERLINK("https://wa.me/57"&G16,"Abrir chat"),"") -> Abrir chat | J16: Cl 30A # 82A-26 | K16: Por contactar | M16: =IF(L16="","",L16+4) | O16: =IF(N16="","",INDEX(Planes!$B$4:$B$6,MATCH(N16,Planes!$A$4:$A$6,0))) | P16: Enviar mensaje 1b | R16: Menú en línea con pedidos a WhatsApp (ola.click) | S16: =HYPERLINK("https://casa-del-arroz.ola.click/","Ver fuente") -> Ver fuente
A17: 16 | B17: Alta | C17: Comidas Rápidas de la Villa | D17: Medellín | E17: Belén | F17: Comida rápida | G17: 3015745474 | H17: =IF(G17="","Sin número",IF(LEFT(G17,1)="3","Celular","Fijo")) -> Celular | I17: =IF(H17="Celular",HYPERLINK("https://wa.me/57"&G17,"Abrir chat"),"") -> Abrir chat | J17: Cra 81 # 32C-2 | K17: Por contactar | M17: =IF(L17="","",L17+4) | O17: =IF(N17="","",INDEX(Planes!$B$4:$B$6,MATCH(N17,Planes!$A$4:$A$6,0))) | P17: Enviar mensaje 1b | R17: Menú en línea con pedidos a WhatsApp (ola.click) | S17: =HYPERLINK("https://comidas-rapidas-juan.ola.click/","Ver fuente") -> Ver fuente
A18: 17 | B18: Alta | C18: Comidas Rápidas DTia | D18: Medellín | E18: Aranjuez | F18: Comida rápida | G18: 3002025959 | H18: =IF(G18="","Sin número",IF(LEFT(G18,1)="3","Celular","Fijo")) -> Celular | I18: =IF(H18="Celular",HYPERLINK("https://wa.me/57"&G18,"Abrir chat"),"") -> Abrir chat | J18: Cra 53 # 94-71 | K18: Por contactar | M18: =IF(L18="","",L18+4) | O18: =IF(N18="","",INDEX(Planes!$B$4:$B$6,MATCH(N18,Planes!$A$4:$A$6,0))) | P18: Enviar mensaje 1b | R18: Menú en línea con pedidos a WhatsApp (ola.click) | S18: =HYPERLINK("https://comidasrapidas-dtia.ola.click/","Ver fuente") -> Ver fuente
A19: 18 | B19: Alta | C19: Correo Carne y Vino | D19: Medellín | E19: Laureles | F19: Restaurante con domicilios | G19: 3107693578 | H19: =IF(G19="","Sin número",IF(LEFT(G19,1)="3","Celular","Fijo")) -> Celular | I19: =IF(H19="Celular",HYPERLINK("https://wa.me/57"&G19,"Abrir chat"),"") -> Abrir chat | K19: Por contactar | M19: =IF(L19="","",L19+4) | O19: =IF(N19="","",INDEX(Planes!$B$4:$B$6,MATCH(N19,Planes!$A$4:$A$6,0))) | P19: Enviar mensaje 1b | R19: Domicilios por WhatsApp (guía de 2020) | S19: =HYPERLINK("https://medellinguru.com/?p=24707","Ver fuente") -> Ver fuente
A20: 19 | B20: Alta | C20: CR Delicias del Barrio | D20: Medellín | E20: Aranjuez | F20: Comida casera | G20: 3135566907 | H20: =IF(G20="","Sin número",IF(LEFT(G20,1)="3","Celular","Fijo")) -> Celular | I20: =IF(H20="Celular",HYPERLINK("https://wa.me/57"&G20,"Abrir chat"),"") -> Abrir chat | J20: Cl 85 # 57A-99 | K20: Por contactar | M20: =IF(L20="","",L20+4) | O20: =IF(N20="","",INDEX(Planes!$B$4:$B$6,MATCH(N20,Planes!$A$4:$A$6,0))) | P20: Enviar mensaje 1b | R20: Menú en línea con pedidos a WhatsApp (ola.click) | S20: =HYPERLINK("https://cr-delicias-del-barrio.ola.click/","Ver fuente") -> Ver fuente
A21: 20 | B21: Alta | C21: Criollas House | D21: Medellín | F21: Comida rápida | G21: 3246020193 | H21: =IF(G21="","Sin número",IF(LEFT(G21,1)="3","Celular","Fijo")) -> Celular | I21: =IF(H21="Celular",HYPERLINK("https://wa.me/57"&G21,"Abrir chat"),"") -> Abrir chat | J21: Cl 91 # 50C-43 | K21: Por contactar | M21: =IF(L21="","",L21+4) | O21: =IF(N21="","",INDEX(Planes!$B$4:$B$6,MATCH(N21,Planes!$A$4:$A$6,0))) | P21: Enviar mensaje 1b | R21: Menú en línea con pedidos a WhatsApp (ola.click) | S21: =HYPERLINK("https://criollashouse.ola.click/","Ver fuente") -> Ver fuente
A22: 21 | B22: Alta | C22: Deliperros y Parrilla | D22: Medellín | F22: Comida rápida | G22: 3206544335 | H22: =IF(G22="","Sin número",IF(LEFT(G22,1)="3","Celular","Fijo")) -> Celular | I22: =IF(H22="Celular",HYPERLINK("https://wa.me/57"&G22,"Abrir chat"),"") -> Abrir chat | J22: Cl 60 # 75-40 | K22: Por contactar | M22: =IF(L22="","",L22+4) | O22: =IF(N22="","",INDEX(Planes!$B$4:$B$6,MATCH(N22,Planes!$A$4:$A$6,0))) | P22: Enviar mensaje 1b | R22: Menú en línea con pedidos a WhatsApp (ola.click) | S22: =HYPERLINK("https://deliperrosyparrilla.ola.click/","Ver fuente") -> Ver fuente
A23: 22 | B23: Alta | C23: Delirio Exquisito | D23: Medellín | E23: El Poblado / Laureles | F23: Restaurante con domicilios | G23: 3113663840 | H23: =IF(G23="","Sin número",IF(LEFT(G23,1)="3","Celular","Fijo")) -> Celular | I23: =IF(H23="Celular",HYPERLINK("https://wa.me/57"&G23,"Abrir chat"),"") -> Abrir chat | K23: Por contactar | M23: =IF(L23="","",L23+4) | O23: =IF(N23="","",INDEX(Planes!$B$4:$B$6,MATCH(N23,Planes!$A$4:$A$6,0))) | P23: Enviar mensaje 1b | Q23: Otro número: 3505671075 | R23: Domicilios por WhatsApp (guía de 2020) | S23: =HYPERLINK("https://medellinguru.com/?p=24612","Ver fuente") -> Ver fuente
A24: 23 | B24: Alta | C24: Due Amici Pizzería | D24: Medellín | E24: Laureles | F24: Pizzería | G24: 3107693578 | H24: =IF(G24="","Sin número",IF(LEFT(G24,1)="3","Celular","Fijo")) -> Celular | I24: =IF(H24="Celular",HYPERLINK("https://wa.me/57"&G24,"Abrir chat"),"") -> Abrir chat | K24: Por contactar | M24: =IF(L24="","",L24+4) | O24: =IF(N24="","",INDEX(Planes!$B$4:$B$6,MATCH(N24,Planes!$A$4:$A$6,0))) | P24: Enviar mensaje 1b | R24: Domicilios por WhatsApp (guía de 2020); el mismo número aparece para Correo Carne y Vino | S24: =HYPERLINK("https://medellinguru.com/laureles-with-domicilio/","Ver fuente") -> Ver fuente
A25: 24 | B25: Alta | C25: El Puto Taco | D25: Medellín | E25: Laureles | F25: Comida mexicana | H25: =IF(G25="","Sin número",IF(LEFT(G25,1)="3","Celular","Fijo")) -> Sin número | I25: =IF(H25="Celular",HYPERLINK("https://wa.me/57"&G25,"Abrir chat"),"") | J25: Tv 5A # 45-337 | K25: Por contactar | M25: =IF(L25="","",L25+4) | O25: =IF(N25="","",INDEX(Planes!$B$4:$B$6,MATCH(N25,Planes!$A$4:$A$6,0))) | P25: Escribir por el botón de WhatsApp de su menú en línea | R25: Menú en línea con pedidos a WhatsApp (ola.click) | S25: =HYPERLINK("https://elputotaco2.ola.click/products","Ver fuente") -> Ver fuente
A26: 25 | B26: Alta | C26: Escudero's BBQ | D26: Medellín | E26: Guayabal | F26: Parrilla | G26: 3017478418 | H26: =IF(G26="","Sin número",IF(LEFT(G26,1)="3","Celular","Fijo")) -> Celular | I26: =IF(H26="Celular",HYPERLINK("https://wa.me/57"&G26,"Abrir chat"),"") -> Abrir chat | J26: Cl 1 # 53-62 | K26: Por contactar | M26: =IF(L26="","",L26+4) | O26: =IF(N26="","",INDEX(Planes!$B$4:$B$6,MATCH(N26,Planes!$A$4:$A$6,0))) | P26: Enviar mensaje 1b | R26: Menú en línea con pedidos a WhatsApp (ola.click) | S26: =HYPERLINK("https://escuderosbbq.ola.click/","Ver fuente") -> Ver fuente
A27: 26 | B27: Alta | C27: Freedog Oviedo | D27: Medellín | E27: El Poblado | F27: Comida rápida | H27: =IF(G27="","Sin número",IF(LEFT(G27,1)="3","Celular","Fijo")) -> Sin número | I27: =IF(H27="Celular",HYPERLINK("https://wa.me/57"&G27,"Abrir chat"),"") | J27: Cra 43A # 6 Sur-15 | K27: Por contactar | M27: =IF(L27="","",L27+4) | O27: =IF(N27="","",INDEX(Planes!$B$4:$B$6,MATCH(N27,Planes!$A$4:$A$6,0))) | P27: Escribir por el botón de WhatsApp de su menú en línea | R27: Menú en línea con pedidos a WhatsApp (ola.click) | S27: =HYPERLINK("https://freedogcolombia.ola.click/","Ver fuente") -> Ver fuente
A28: 27 | B28: Alta | C28: Kuelap | D28: Medellín | E28: El Poblado | F28: Restaurante peruano | G28: 3164312245 | H28: =IF(G28="","Sin número",IF(LEFT(G28,1)="3","Celular","Fijo")) -> Celular | I28: =IF(H28="Celular",HYPERLINK("https://wa.me/57"&G28,"Abrir chat"),"") -> Abrir chat | J28: Cl 3 Sur # 43A-40 | K28: Por contactar | M28: =IF(L28="","",L28+4) | O28: =IF(N28="","",INDEX(Planes!$B$4:$B$6,MATCH(N28,Planes!$A$4:$A$6,0))) | P28: Enviar mensaje 1b | R28: Domicilios por WhatsApp (guía de 2020) | S28: =HYPERLINK("https://medellinguru.com/kuelap/","Ver fuente") -> Ver fuente
A29: 28 | B29: Alta | C29: La Chimichanga | D29: Medellín | E29: Belén | F29: Comida mexicana | G29: 3015312571 | H29: =IF(G29="","Sin número",IF(LEFT(G29,1)="3","Celular","Fijo")) -> Celular | I29: =IF(H29="Celular",HYPERLINK("https://wa.me/57"&G29,"Abrir chat"),"") -> Abrir chat | J29: Cl 3C # 77A-14 | K29: Por contactar | M29: =IF(L29="","",L29+4) | O29: =IF(N29="","",INDEX(Planes!$B$4:$B$6,MATCH(N29,Planes!$A$4:$A$6,0))) | P29: Enviar mensaje 1b | R29: Menú en línea con pedidos a WhatsApp (ola.click) | S29: =HYPERLINK("https://lachimichanga.ola.click/","Ver fuente") -> Ver fuente
A30: 29 | B30: Alta | C30: La Chorizería | D30: Medellín | E30: Laureles | F30: Comida rápida | G30: 3112073817 | H30: =IF(G30="","Sin número",IF(LEFT(G30,1)="3","Celular","Fijo")) -> Celular | I30: =IF(H30="Celular",HYPERLINK("https://wa.me/57"&G30,"Abrir chat"),"") -> Abrir chat | J30: Cl 35 # 80A-70 | K30: Por contactar | M30: =IF(L30="","",L30+4) | O30: =IF(N30="","",INDEX(Planes!$B$4:$B$6,MATCH(N30,Planes!$A$4:$A$6,0))) | P30: Enviar mensaje 1b | R30: Menú en línea con pedidos a WhatsApp (ola.click) | S30: =HYPERLINK("https://la-choriceria.ola.click/","Ver fuente") -> Ver fuente
A31: 30 | B31: Alta | C31: La Eterna | D31: Medellín | E31: La Candelaria | F31: Restaurante | G31: 3107364695 | H31: =IF(G31="","Sin número",IF(LEFT(G31,1)="3","Celular","Fijo")) -> Celular | I31: =IF(H31="Celular",HYPERLINK("https://wa.me/57"&G31,"Abrir chat"),"") -> Abrir chat | J31: Cra 50D # 66-39 | K31: Por contactar | M31: =IF(L31="","",L31+4) | O31: =IF(N31="","",INDEX(Planes!$B$4:$B$6,MATCH(N31,Planes!$A$4:$A$6,0))) | P31: Enviar mensaje 1b | R31: Menú en línea con pedidos a WhatsApp (ola.click) | S31: =HYPERLINK("https://la-eterna-2.ola.click/","Ver fuente") -> Ver fuente
A32: 31 | B32: Alta | C32: La Locura de Celia | D32: Medellín | E32: Laureles | F32: Asadero | H32: =IF(G32="","Sin número",IF(LEFT(G32,1)="3","Celular","Fijo")) -> Sin número | I32: =IF(H32="Celular",HYPERLINK("https://wa.me/57"&G32,"Abrir chat"),"") | J32: Cra 80A # 35-13 | K32: Por contactar | M32: =IF(L32="","",L32+4) | O32: =IF(N32="","",INDEX(Planes!$B$4:$B$6,MATCH(N32,Planes!$A$4:$A$6,0))) | P32: Escribir por el botón de WhatsApp de su menú en línea | R32: Menú en línea con pedidos a WhatsApp (ola.click) | S32: =HYPERLINK("https://la-locura-de-celia-asado-restaurante.ola.click/","Ver fuente") -> Ver fuente
A33: 32 | B33: Alta | C33: La Sazón de ALDE | D33: Medellín | E33: Laureles | F33: Comida casera | G33: 3013894096 | H33: =IF(G33="","Sin número",IF(LEFT(G33,1)="3","Celular","Fijo")) -> Celular | I33: =IF(H33="Celular",HYPERLINK("https://wa.me/57"&G33,"Abrir chat"),"") -> Abrir chat | J33: Av Bolivariana # 42B-16 | K33: Por contactar | M33: =IF(L33="","",L33+4) | O33: =IF(N33="","",INDEX(Planes!$B$4:$B$6,MATCH(N33,Planes!$A$4:$A$6,0))) | P33: Enviar mensaje 1b | R33: Menú en línea con pedidos a WhatsApp (ola.click) | S33: =HYPERLINK("https://lasazondealde.ola.click/","Ver fuente") -> Ver fuente
A34: 33 | B34: Alta | C34: Lo Exquisito del Mar | D34: Medellín | E34: Laureles | F34: Comida de mar | G34: 3194189670 | H34: =IF(G34="","Sin número",IF(LEFT(G34,1)="3","Celular","Fijo")) -> Celular | I34: =IF(H34="Celular",HYPERLINK("https://wa.me/57"&G34,"Abrir chat"),"") -> Abrir chat | K34: Por contactar | M34: =IF(L34="","",L34+4) | O34: =IF(N34="","",INDEX(Planes!$B$4:$B$6,MATCH(N34,Planes!$A$4:$A$6,0))) | P34: Enviar mensaje 1b | R34: Domicilios por WhatsApp (guía de 2020; también 3023301037) | S34: =HYPERLINK("https://medellinguru.com/laureles-with-domicilio/","Ver fuente") -> Ver fuente
A35: 34 | B35: Alta | C35: Los Costeñitos Exprés | D35: Medellín | E35: Laureles | F35: Comida costeña | G35: 3217791979 | H35: =IF(G35="","Sin número",IF(LEFT(G35,1)="3","Celular","Fijo")) -> Celular | I35: =IF(H35="Celular",HYPERLINK("https://wa.me/57"&G35,"Abrir chat"),"") -> Abrir chat | J35: Cra 74 # 53-162 | K35: Por contactar | M35: =IF(L35="","",L35+4) | O35: =IF(N35="","",INDEX(Planes!$B$4:$B$6,MATCH(N35,Planes!$A$4:$A$6,0))) | P35: Enviar mensaje 1b | R35: Menú en línea con pedidos a WhatsApp (ola.click) | S35: =HYPERLINK("https://los-costenitos-expres.ola.click/","Ver fuente") -> Ver fuente
A36: 35 | B36: Alta | C36: Lupita Cocina Peruana | D36: Medellín | E36: Centro | F36: Restaurante peruano | G36: 3177178229 | H36: =IF(G36="","Sin número",IF(LEFT(G36,1)="3","Celular","Fijo")) -> Celular | I36: =IF(H36="Celular",HYPERLINK("https://wa.me/57"&G36,"Abrir chat"),"") -> Abrir chat | J36: Cra 43 # 52-101 | K36: Por contactar | M36: =IF(L36="","",L36+4) | O36: =IF(N36="","",INDEX(Planes!$B$4:$B$6,MATCH(N36,Planes!$A$4:$A$6,0))) | P36: Enviar mensaje 1b | R36: Menú en línea con pedidos a WhatsApp (ola.click) | S36: =HYPERLINK("https://lupita-col.ola.click/","Ver fuente") -> Ver fuente
A37: 36 | B37: Alta | C37: Mr. Will Restaurante | D37: Medellín | E37: Laureles | F37: Restaurante | G37: 3187587404 | H37: =IF(G37="","Sin número",IF(LEFT(G37,1)="3","Celular","Fijo")) -> Celular | I37: =IF(H37="Celular",HYPERLINK("https://wa.me/57"&G37,"Abrir chat"),"") -> Abrir chat | J37: Cra 69A # 44B-115 | K37: Por contactar | M37: =IF(L37="","",L37+4) | O37: =IF(N37="","",INDEX(Planes!$B$4:$B$6,MATCH(N37,Planes!$A$4:$A$6,0))) | P37: Enviar mensaje 1b | R37: Menú en línea con pedidos a WhatsApp (ola.click) | S37: =HYPERLINK("https://restaurantemrwill.ola.click/","Ver fuente") -> Ver fuente
A38: 37 | B38: Alta | C38: Muzarella's Pizza | D38: Medellín | E38: Robledo | F38: Pizzería | H38: =IF(G38="","Sin número",IF(LEFT(G38,1)="3","Celular","Fijo")) -> Sin número | I38: =IF(H38="Celular",HYPERLINK("https://wa.me/57"&G38,"Abrir chat"),"") | J38: Villa Flora | K38: Por contactar | M38: =IF(L38="","",L38+4) | O38: =IF(N38="","",INDEX(Planes!$B$4:$B$6,MATCH(N38,Planes!$A$4:$A$6,0))) | P38: Escribir por el botón de WhatsApp de su menú en línea | R38: Menú en línea con pedidos a WhatsApp (ola.click) | S38: =HYPERLINK("https://muzarellas-pizza.ola.click/","Ver fuente") -> Ver fuente
A39: 38 | B39: Alta | C39: Parrilla Bar Nogales Barbecue | D39: Medellín | E39: Belén | F39: Parrilla | G39: 3103758138 | H39: =IF(G39="","Sin número",IF(LEFT(G39,1)="3","Celular","Fijo")) -> Celular | I39: =IF(H39="Celular",HYPERLINK("https://wa.me/57"&G39,"Abrir chat"),"") -> Abrir chat | J39: Cl 32EE # 78-109 | K39: Por contactar | M39: =IF(L39="","",L39+4) | O39: =IF(N39="","",INDEX(Planes!$B$4:$B$6,MATCH(N39,Planes!$A$4:$A$6,0))) | P39: Enviar mensaje 1b | R39: Menú en línea con pedidos a WhatsApp (ola.click) | S39: =HYPERLINK("https://parrilla-nogales-barbecue.ola.click/","Ver fuente") -> Ver fuente
A40: 39 | B40: Alta | C40: Parrillas Caracas | D40: Medellín | E40: Laureles | F40: Parrilla | H40: =IF(G40="","Sin número",IF(LEFT(G40,1)="3","Celular","Fijo")) -> Sin número | I40: =IF(H40="Celular",HYPERLINK("https://wa.me/57"&G40,"Abrir chat"),"") | J40: Cra 78 # 45A-04 | K40: Por contactar | M40: =IF(L40="","",L40+4) | O40: =IF(N40="","",INDEX(Planes!$B$4:$B$6,MATCH(N40,Planes!$A$4:$A$6,0))) | P40: Escribir por el botón de WhatsApp de su menú en línea | R40: Menú en línea con pedidos a WhatsApp (ola.click) | S40: =HYPERLINK("https://parrillas-caracas.ola.click/","Ver fuente") -> Ver fuente
...

Sheet Resumen
A1: Resumen de la prospección
A2: Se actualiza solo a medida que cambia la columna Estado en Restaurantes.
A4: Estado | B4: Restaurantes | C4: % del total
A5: Por contactar | B5: =COUNTIF(Restaurantes!$K$2:$K$153,A5) -> 152 | C5: =IF($B$13=0,0,B5/$B$13) -> 1
A6: Mensaje enviado | B6: =COUNTIF(Restaurantes!$K$2:$K$153,A6) -> 0 | C6: =IF($B$13=0,0,B6/$B$13) -> 0
A7: Respondió | B7: =COUNTIF(Restaurantes!$K$2:$K$153,A7) -> 0 | C7: =IF($B$13=0,0,B7/$B$13) -> 0
A8: Demo agendada | B8: =COUNTIF(Restaurantes!$K$2:$K$153,A8) -> 0 | C8: =IF($B$13=0,0,B8/$B$13) -> 0
A9: En prueba | B9: =COUNTIF(Restaurantes!$K$2:$K$153,A9) -> 0 | C9: =IF($B$13=0,0,B9/$B$13) -> 0
A10: Cliente | B10: =COUNTIF(Restaurantes!$K$2:$K$153,A10) -> 0 | C10: =IF($B$13=0,0,B10/$B$13) -> 0
A11: No interesado | B11: =COUNTIF(Restaurantes!$K$2:$K$153,A11) -> 0 | C11: =IF($B$13=0,0,B11/$B$13) -> 0
A12: Número errado | B12: =COUNTIF(Restaurantes!$K$2:$K$153,A12) -> 0 | C12: =IF($B$13=0,0,B12/$B$13) -> 0
A13: Total | B13: =COUNTA(Restaurantes!$C$2:$C$153) -> 152 | C13: =IF($B$13=0,0,B13/$B$13) -> 1
A15: Indicadores
A16: Contactados (todo menos Por contactar) | B16: =B13-B5 -> 0
A17: Tasa de respuesta | B17: =IF(B16=0,0,(B7+B8+B9+B10+B11)/B16) -> 0
A18: Demos, pruebas y clientes | B18: =B8+B9+B10 -> 0
A19: Clientes | B19: =B10 -> 0
A20: Ingreso mensual de clientes (COP) | B20: =SUMIFS(Restaurantes!$O$2:$O$153,Restaurantes!$K$2:$K$153,"Cliente") -> 0
A21: Seguimientos vencidos hoy | B21: =COUNTIFS(Restaurantes!$K$2:$K$153,"Mensaje enviado",Restaurantes!$M$2:$M$153,"<="&TODAY()) -> 0
A22: Restaurantes con celular | B22: =COUNTIF(Restaurantes!$H$2:$H$153,"Celular") -> 109
A23: Restaurantes en Medellín | B23: =COUNTIF(Restaurantes!$D$2:$D$153,"Medellín") -> 126
A24: Restaurantes en Bello | B24: =COUNTIF(Restaurantes!$D$2:$D$153,"Bello") -> 26
A25: Prioridad alta (ya venden por WhatsApp) | B25: =COUNTIF(Restaurantes!$B$2:$B$153,"Alta") -> 48
A26: Prioridad media | B26: =COUNTIF(Restaurantes!$B$2:$B$153,"Media") -> 49
A27: Prioridad baja | B27: =COUNTIF(Restaurantes!$B$2:$B$153,"Baja") -> 55

Sheet Planes
A1: Planes y precios
A3: Plan | B3: Mensualidad (COP) | C3: Instalación (COP) | D3: Impresora opcional (COP) | E3: Incluye
A4: Básico | B4: 350000 | C4: 200000 | D4: No disponible | E4: Bot de pedidos (menú, catálogo, audios), IA del administrador, domicilios por zona y efectivo. Transferencias las confirma una persona.
A5: Avanzado | B5: 450000 | C5: 200000 | D5: 350000 | E5: Todo lo del Básico, y el bot lee el comprobante de transferencia. Impresora de comandas opcional.
A6: Premium | B6: 550000 | C6: 200000 | D6: 350000 | E6: Todo lo del Avanzado, más domiciliarios con liquidación y cierre diario, estadísticas, consultas de pedidos y Excel.
A9: Fuente: tabla de planes del panel, enviada por el dueño del producto (28-oct-2026).

Sheet Mensajes
A1: Mensajes para WhatsApp (uno por uno, desde el número de ventas)
A3: 1. Primer mensaje | B3: Buenas, ¿hablo con el restaurante {nombre}? Mi nombre es {su nombre}, le escribo desde Medellín. Hicimos un asistente para el WhatsApp de restaurantes: le contesta a los clientes, toma el pedido completo con la dirección y le calcula el domicilio según el barrio. El menú del día se carga mandando una foto. ¿Le puedo mostrar cómo funciona?
A4: 1b. Ya venden por WhatsApp | B4: Buenas, ¿hablo con {nombre}? Mi nombre es {su nombre}. Vi que reciben los pedidos por WhatsApp. A la hora del almuerzo, ¿quién contesta todos esos mensajes? Tenemos un asistente que los contesta solo: toma el pedido, confirma la dirección, calcula el domicilio, revisa el comprobante de la transferencia y le manda la comanda a la cocina. Usted solo revisa. ¿Le muestro cómo quedaría con su menú?
A5: 2. Si hacen domicilios | B5: Hola, vi que {nombre} hace domicilios por WhatsApp. A la hora del almuerzo se llenan los mensajes y alguien tiene que contestar uno por uno, ¿cierto? Tenemos un asistente que contesta, toma el pedido y se lo deja listo. Si quiere, la comanda le sale impresa en la cocina. ¿Le gustaría verlo funcionando con su propio menú?
A6: 3. Seguimiento (una sola vez) | B6: Hola de nuevo. Le escribí la semana pasada por el asistente de pedidos para WhatsApp. Si quiere, le preparo una prueba con el menú de {nombre} de esta semana y usted mismo le escribe como si fuera un cliente. ¿Le sirve?
A7: 4. Cuando dicen que sí | B7: Listo, con mucho gusto. Mándeme una foto del menú de hoy y los barrios a donde hace domicilios con el valor de cada uno. Con eso se lo dejo armado y le paso el número para que pruebe.
A8: 5. Llamada a un fijo | B8: Buenas, ¿con el restaurante {nombre}? Le habla {su nombre}. ¿Ustedes reciben pedidos por WhatsApp? Le pregunto porque tenemos un asistente que los contesta y toma el pedido completo. ¿Me regala un celular para mandarle cómo funciona?
A9: Si dicen que no | B9: Listo, no le vuelvo a escribir. Que le vaya muy bien.

Sheet Cómo usar
A1: Cómo usar esta hoja
A3: 1. Empiece por la prioridad Alta: son restaurantes que ya reciben pedidos por WhatsApp (tienen menú en línea que manda el pedido a WhatsApp, o publican su WhatsApp para domicilios). Media: tipo de negocio que suele vender a domicilio y con celular, pero sin prueba de que use WhatsApp. Baja: cafés, bares, restaurantes de mesa o solo con fijo.
A4: 2. Las celdas amarillas de Restaurantes son las que usted llena: Estado, Primer contacto, Plan de interés, Próxima acción y Notas. Lo demás se calcula solo.
A5: 3. Ejemplo: escribe por WhatsApp a un restaurante → Estado = Mensaje enviado, Primer contacto = 28/10/2026. La columna Seguimiento muestra 01/11/2026 y se pone en rojo cuando ya toca escribir de nuevo.
A6: 4. La columna WhatsApp abre el chat directo con el celular del restaurante. Los fijos (604...) se llaman: use el mensaje 5 de la pestaña Mensajes.
A7: 5. Cuando alguien escoja un plan, márquelo en Plan de interés; la mensualidad sale de la pestaña Planes.
A8: 6. Si el número no existe o es de otro negocio, Estado = Número errado.
A9: 7. Para no arriesgar el número de ventas: 30 a 40 mensajes al día, uno por uno, nunca desde el número del bot.
A10: 8. Origen de los datos: páginas de menú en línea de cada restaurante (ola.click), directorios de empresas registradas (informacolombia.com y einforma.co) y guías de restaurantes con domicilio (medellinguru.com, varias de 2020). Son registros públicos que pueden estar desactualizados; la columna Fuente lleva a la ficha de cada uno.
A11: 9. Para conseguir más restaurantes: python3 ventas/buscar_restaurantes.py --solo-contactables (necesita acceso a OpenStreetMap).
